INFO:root:(0 points) os.path.isfile("lab2.r") is True
INFO:root:Executed R('load(\'test-vars.rda\')')
INFO:root:Executed R('load(\'prostatedata.Rda\')')
INFO:root:(2 points) R('all.equal(n.prostate, sum(colnames(prost.data) == 2))')[0] is True
ERROR:root:(2 points) Checking R('all.equal(unname(status.means), unname(apply(prost.data, 1, function(gene) by(gene, names(gene), mean))))')[0]
ERROR:root:... Expecting: True
ERROR:root:... But got:   Mean relative difference: 1.149184
ERROR:root:(2 points) Checking R('all.equal(unname(status.trim.means), unname(apply(prost.data, 1, function(gene) by(gene, names(gene), mean, trim=0.1))))')[0]
ERROR:root:... Expecting: True
ERROR:root:... But got:   Mean relative difference: 1.02621
ERROR:root:(2 points) Checking R('all.equal(quantile.cutoff.t, quantileCutoff(test.data, 0.25, 10))')[0]
ERROR:root:... Expecting: True
ERROR:root:... But got:   Modes: numeric, logical
ERROR:root:(2 points) Checking R('all.equal(c(4,8,14), quantileCutoff(prost.data[1:20, 1:50], 0.1, 10))')[0]
ERROR:root:... Expecting: True
ERROR:root:... But got:   Modes: numeric, logical
INFO:root:(2 points) R('all.equal(0.5889667, unname(tConvert(test.data[1, ])), tolerance=1e-6)')[0] is True
INFO:root:(2 points) R('all.equal(0.6643303, unname(tConvert(prost.data[2, ])), tolerance=1e-6)')[0] is True
ERROR:root:(2 points) Checking R('all.equal(p.val.converter.t, pValConverter(test.data))')[0]
ERROR:root:... Expecting: True
ERROR:root:... But got:   Mean relative difference: 0.003233734
ERROR:root:(2 points) Checking R('all.equal(c(0.8927677, 0.7532672), pValConverter(prost.data[20:21, 1:80]), tolerance=1e-6)')[0]
ERROR:root:... Expecting: True
ERROR:root:... But got:   Traceback error
ERROR:root:Got exception:
Traceback (most recent call last):
  File "../check.py", line 79, in check
    result = eval(command, g)
  File "<string>", line 1, in <module>
  File "/usr/lib64/python2.7/site-packages/rpy2/robjects/__init__.py", line 240, in __call__
    res = self.eval(p)
  File "/usr/lib64/python2.7/site-packages/rpy2/robjects/functions.py", line 86, in __call__
    return super(SignatureTranslatedFunction, self).__call__(*args, **kwargs)
  File "/usr/lib64/python2.7/site-packages/rpy2/robjects/functions.py", line 35, in __call__
    res = super(Function, self).__call__(*new_args, **new_kwargs)
RRuntimeError: Error in data[i, 51:102] : subscript out of bounds

ERROR:root:Traceback (most recent call last):
  File "../check.py", line 79, in check
    result = eval(command, g)
  File "<string>", line 1, in <module>
  File "/usr/lib64/python2.7/site-packages/rpy2/robjects/__init__.py", line 240, in __call__
    res = self.eval(p)
  File "/usr/lib64/python2.7/site-packages/rpy2/robjects/functions.py", line 86, in __call__
    return super(SignatureTranslatedFunction, self).__call__(*args, **kwargs)
  File "/usr/lib64/python2.7/site-packages/rpy2/robjects/functions.py", line 35, in __call__
    res = super(Function, self).__call__(*new_args, **new_kwargs)
RRuntimeError: Error in data[i, 51:102] : subscript out of bounds

Traceback (most recent call last):
  File "../check.py", line 79, in check
    result = eval(command, g)
  File "<string>", line 1, in <module>
  File "/usr/lib64/python2.7/site-packages/rpy2/robjects/__init__.py", line 240, in __call__
    res = self.eval(p)
  File "/usr/lib64/python2.7/site-packages/rpy2/robjects/functions.py", line 86, in __call__
    return super(SignatureTranslatedFunction, self).__call__(*args, **kwargs)
  File "/usr/lib64/python2.7/site-packages/rpy2/robjects/functions.py", line 35, in __call__
    res = super(Function, self).__call__(*new_args, **new_kwargs)
RRuntimeError: Error in data[i, 51:102] : subscript out of bounds

INFO:root:(2 points) R('all.equal(0.1923077, FDR(prost.data[1:500, ], 0.005), tolerance=1e-6)')[0] is True
INFO:root:(2 points) R('all.equal(0.625, FDR(prost.data[1:100, ], 0.05), tolerance=1e-6)')[0] is True
INFO:root:You got a 10 out of 22.
